{"uid":"c553a4f5a1d3b863","name":"test_initial_greeting","fullName":"tests.integration_mem0.test_peptide_coaching_scenario.TestPeptideCoachingScenario#test_initial_greeting","historyId":"c285e912e9df9f73d2143af53627f203","time":{"start":1748366101430,"stop":1748366101430,"duration":0},"description":"Test initial user greeting and AI response.","descriptionHtml":"<p>Test initial user greeting and AI response.</p>\n","status":"failed","statusMessage":"Failed: Failed to initialize peptide coach: timed out","statusTrace":".venv/lib/python3.12/site-packages/httpx/_transports/default.py:101: in map_httpcore_exceptions\n    yield\n.venv/lib/python3.12/site-packages/httpx/_transports/default.py:250: in handle_request\n    resp = self._pool.handle_request(req)\n.venv/lib/python3.12/site-packages/httpcore/_sync/connection_pool.py:256: in handle_request\n    raise exc from None\n.venv/lib/python3.12/site-packages/httpcore/_sync/connection_pool.py:236: in handle_request\n    response = connection.handle_request(\n.venv/lib/python3.12/site-packages/httpcore/_sync/connection.py:101: in handle_request\n    raise exc\n.venv/lib/python3.12/site-packages/httpcore/_sync/connection.py:78: in handle_request\n    stream = self._connect(request)\n.venv/lib/python3.12/site-packages/httpcore/_sync/connection.py:124: in _connect\n    stream = self._network_backend.connect_tcp(**kwargs)\n.venv/lib/python3.12/site-packages/httpcore/_backends/sync.py:207: in connect_tcp\n    with map_exceptions(exc_map):\n/Library/Frameworks/Python.framework/Versions/3.12/lib/python3.12/contextlib.py:158: in __exit__\n    self.gen.throw(value)\n.venv/lib/python3.12/site-packages/httpcore/_exceptions.py:14: in map_exceptions\n    raise to_exc(exc) from exc\nE   httpcore.ConnectTimeout: timed out\n\nThe above exception was the direct cause of the following exception:\n.venv/lib/python3.12/site-packages/qdrant_client/http/api_client.py:129: in send_inner\n    response = self._client.send(request)\n.venv/lib/python3.12/site-packages/httpx/_client.py:914: in send\n    response = self._send_handling_auth(\n.venv/lib/python3.12/site-packages/httpx/_client.py:942: in _send_handling_auth\n    response = self._send_handling_redirects(\n.venv/lib/python3.12/site-packages/httpx/_client.py:979: in _send_handling_redirects\n    response = self._send_single_request(request)\n.venv/lib/python3.12/site-packages/httpx/_client.py:1014: in _send_single_request\n    response = transport.handle_request(request)\n.venv/lib/python3.12/site-packages/httpx/_transports/default.py:249: in handle_request\n    with map_httpcore_exceptions():\n/Library/Frameworks/Python.framework/Versions/3.12/lib/python3.12/contextlib.py:158: in __exit__\n    self.gen.throw(value)\n.venv/lib/python3.12/site-packages/httpx/_transports/default.py:118: in map_httpcore_exceptions\n    raise mapped_exc(message) from exc\nE   httpx.ConnectTimeout: timed out\n\nDuring handling of the above exception, another exception occurred:\ntests/integration_mem0/test_peptide_coaching_scenario.py:87: in peptide_coach\n    memory = Memory.from_config(config)\n.venv/lib/python3.12/site-packages/mem0/memory/main.py:161: in from_config\n    return cls(config)\n.venv/lib/python3.12/site-packages/mem0/memory/main.py:123: in __init__\n    self.vector_store = VectorStoreFactory.create(\n.venv/lib/python3.12/site-packages/mem0/utils/factory.py:99: in create\n    return vector_store_instance(**config)\n.venv/lib/python3.12/site-packages/mem0/vector_stores/qdrant.py:71: in __init__\n    self.create_col(embedding_model_dims, on_disk)\n.venv/lib/python3.12/site-packages/mem0/vector_stores/qdrant.py:83: in create_col\n    response = self.list_cols()\n.venv/lib/python3.12/site-packages/mem0/vector_stores/qdrant.py:200: in list_cols\n    return self.client.get_collections()\n.venv/lib/python3.12/site-packages/qdrant_client/qdrant_client.py:2214: in get_collections\n    return self._client.get_collections(**kwargs)\n.venv/lib/python3.12/site-packages/qdrant_client/qdrant_remote.py:2571: in get_collections\n    self.http.collections_api.get_collections().result\n.venv/lib/python3.12/site-packages/qdrant_client/http/api/collections_api.py:330: in get_collections\n    return self._build_for_get_collections()\n.venv/lib/python3.12/site-packages/qdrant_client/http/api/collections_api.py:159: in _build_for_get_collections\n    return self.api_client.request(\n.venv/lib/python3.12/site-packages/qdrant_client/http/api_client.py:90: in request\n    return self.send(request, type_)\n.venv/lib/python3.12/site-packages/qdrant_client/http/api_client.py:107: in send\n    response = self.middleware(request, self.send_inner)\n.venv/lib/python3.12/site-packages/qdrant_client/http/api_client.py:240: in __call__\n    return call_next(request)\n.venv/lib/python3.12/site-packages/qdrant_client/http/api_client.py:131: in send_inner\n    raise ResponseHandlingException(e)\nE   qdrant_client.http.exceptions.ResponseHandlingException: timed out\n\nDuring handling of the above exception, another exception occurred:\ntests/integration_mem0/test_peptide_coaching_scenario.py:101: in peptide_coach\n    pytest.fail(f\"Failed to initialize peptide coach: {str(e)}\")\nE   Failed: Failed to initialize peptide coach: timed out","flaky":false,"newFailed":false,"newBroken":false,"newPassed":false,"retriesCount":0,"retriesStatusChange":false,"beforeStages":[{"name":"peptide_coach","time":{"start":1748366101430,"stop":1748366111546,"duration":10116},"status":"failed","statusMessage":"Failed: Failed to initialize peptide coach: timed out\n","statusTrace":"  File \"/Users/samisabir-idrissi/code/ssiautomationsapps/mem01-ai-tutor/.venv/lib/python3.12/site-packages/pluggy/_callers.py\", line 38, in run_old_style_hookwrapper\n    res = yield\n          ^^^^^\n  File \"/Users/samisabir-idrissi/code/ssiautomationsapps/mem01-ai-tutor/.venv/lib/python3.12/site-packages/pluggy/_callers.py\", line 139, in _multicall\n    teardown.throw(exception)\n  File \"/Users/samisabir-idrissi/code/ssiautomationsapps/mem01-ai-tutor/.venv/lib/python3.12/site-packages/pluggy/_callers.py\", line 53, in run_old_style_hookwrapper\n    return result.get_result()\n           ^^^^^^^^^^^^^^^^^^^\n  File \"/Users/samisabir-idrissi/code/ssiautomationsapps/mem01-ai-tutor/.venv/lib/python3.12/site-packages/pluggy/_result.py\", line 103, in get_result\n    raise exc.with_traceback(tb)\n  File \"/Users/samisabir-idrissi/code/ssiautomationsapps/mem01-ai-tutor/.venv/lib/python3.12/site-packages/pluggy/_callers.py\", line 38, in run_old_style_hookwrapper\n    res = yield\n          ^^^^^\n  File \"/Users/samisabir-idrissi/code/ssiautomationsapps/mem01-ai-tutor/.venv/lib/python3.12/site-packages/pluggy/_callers.py\", line 139, in _multicall\n    teardown.throw(exception)\n  File \"/Users/samisabir-idrissi/code/ssiautomationsapps/mem01-ai-tutor/.venv/lib/python3.12/site-packages/_pytest/setuponly.py\", line 36, in pytest_fixture_setup\n    return (yield)\n            ^^^^^\n  File \"/Users/samisabir-idrissi/code/ssiautomationsapps/mem01-ai-tutor/.venv/lib/python3.12/site-packages/pluggy/_callers.py\", line 121, in _multicall\n    res = hook_impl.function(*args)\n          ^^^^^^^^^^^^^^^^^^^^^^^^^\n  File \"/Users/samisabir-idrissi/code/ssiautomationsapps/mem01-ai-tutor/.venv/lib/python3.12/site-packages/_pytest/fixtures.py\", line 1140, in pytest_fixture_setup\n    result = call_fixture_func(fixturefunc, request, kwargs)\n             ^^^^^^^^^^^^^^^^^^^^^^^^^^^^^^^^^^^^^^^^^^^^^^^\n  File \"/Users/samisabir-idrissi/code/ssiautomationsapps/mem01-ai-tutor/.venv/lib/python3.12/site-packages/_pytest/fixtures.py\", line 898, in call_fixture_func\n    fixture_result = fixturefunc(**kwargs)\n                     ^^^^^^^^^^^^^^^^^^^^^\n  File \"/Users/samisabir-idrissi/code/ssiautomationsapps/mem01-ai-tutor/tests/integration_mem0/test_peptide_coaching_scenario.py\", line 101, in peptide_coach\n    pytest.fail(f\"Failed to initialize peptide coach: {str(e)}\")\n  File \"/Users/samisabir-idrissi/code/ssiautomationsapps/mem01-ai-tutor/.venv/lib/python3.12/site-packages/_pytest/outcomes.py\", line 178, in fail\n    raise Failed(msg=reason, pytrace=pytrace)\n","steps":[{"name":"Initializing Peptide Coaching Assistant","time":{"start":1748366101430,"stop":1748366111532,"duration":10102},"status":"failed","statusMessage":"Failed: Failed to initialize peptide coach: timed out\n","statusTrace":"  File \"/Users/samisabir-idrissi/code/ssiautomationsapps/mem01-ai-tutor/tests/integration_mem0/test_peptide_coaching_scenario.py\", line 101, in peptide_coach\n    pytest.fail(f\"Failed to initialize peptide coach: {str(e)}\")\n  File \"/Users/samisabir-idrissi/code/ssiautomationsapps/mem01-ai-tutor/.venv/lib/python3.12/site-packages/_pytest/outcomes.py\", line 178, in fail\n    raise Failed(msg=reason, pytrace=pytrace)\n","steps":[],"attachments":[{"uid":"8fe2e4141dc871ad","name":"Mem0 Configuration","source":"8fe2e4141dc871ad.txt","type":"text/plain","size":307},{"uid":"f5a8068ccb3b968f","name":"Initialization Error","source":"f5a8068ccb3b968f.txt","type":"text/plain","size":9}],"parameters":[],"shouldDisplayMessage":true,"stepsCount":0,"attachmentsCount":2,"hasContent":true,"attachmentStep":false}],"attachments":[],"parameters":[],"shouldDisplayMessage":false,"stepsCount":1,"attachmentsCount":2,"hasContent":true,"attachmentStep":false}],"testStage":{"description":"Test initial user greeting and AI response.","status":"failed","statusMessage":"Failed: Failed to initialize peptide coach: timed out","statusTrace":".venv/lib/python3.12/site-packages/httpx/_transports/default.py:101: in map_httpcore_exceptions\n    yield\n.venv/lib/python3.12/site-packages/httpx/_transports/default.py:250: in handle_request\n    resp = self._pool.handle_request(req)\n.venv/lib/python3.12/site-packages/httpcore/_sync/connection_pool.py:256: in handle_request\n    raise exc from None\n.venv/lib/python3.12/site-packages/httpcore/_sync/connection_pool.py:236: in handle_request\n    response = connection.handle_request(\n.venv/lib/python3.12/site-packages/httpcore/_sync/connection.py:101: in handle_request\n    raise exc\n.venv/lib/python3.12/site-packages/httpcore/_sync/connection.py:78: in handle_request\n    stream = self._connect(request)\n.venv/lib/python3.12/site-packages/httpcore/_sync/connection.py:124: in _connect\n    stream = self._network_backend.connect_tcp(**kwargs)\n.venv/lib/python3.12/site-packages/httpcore/_backends/sync.py:207: in connect_tcp\n    with map_exceptions(exc_map):\n/Library/Frameworks/Python.framework/Versions/3.12/lib/python3.12/contextlib.py:158: in __exit__\n    self.gen.throw(value)\n.venv/lib/python3.12/site-packages/httpcore/_exceptions.py:14: in map_exceptions\n    raise to_exc(exc) from exc\nE   httpcore.ConnectTimeout: timed out\n\nThe above exception was the direct cause of the following exception:\n.venv/lib/python3.12/site-packages/qdrant_client/http/api_client.py:129: in send_inner\n    response = self._client.send(request)\n.venv/lib/python3.12/site-packages/httpx/_client.py:914: in send\n    response = self._send_handling_auth(\n.venv/lib/python3.12/site-packages/httpx/_client.py:942: in _send_handling_auth\n    response = self._send_handling_redirects(\n.venv/lib/python3.12/site-packages/httpx/_client.py:979: in _send_handling_redirects\n    response = self._send_single_request(request)\n.venv/lib/python3.12/site-packages/httpx/_client.py:1014: in _send_single_request\n    response = transport.handle_request(request)\n.venv/lib/python3.12/site-packages/httpx/_transports/default.py:249: in handle_request\n    with map_httpcore_exceptions():\n/Library/Frameworks/Python.framework/Versions/3.12/lib/python3.12/contextlib.py:158: in __exit__\n    self.gen.throw(value)\n.venv/lib/python3.12/site-packages/httpx/_transports/default.py:118: in map_httpcore_exceptions\n    raise mapped_exc(message) from exc\nE   httpx.ConnectTimeout: timed out\n\nDuring handling of the above exception, another exception occurred:\ntests/integration_mem0/test_peptide_coaching_scenario.py:87: in peptide_coach\n    memory = Memory.from_config(config)\n.venv/lib/python3.12/site-packages/mem0/memory/main.py:161: in from_config\n    return cls(config)\n.venv/lib/python3.12/site-packages/mem0/memory/main.py:123: in __init__\n    self.vector_store = VectorStoreFactory.create(\n.venv/lib/python3.12/site-packages/mem0/utils/factory.py:99: in create\n    return vector_store_instance(**config)\n.venv/lib/python3.12/site-packages/mem0/vector_stores/qdrant.py:71: in __init__\n    self.create_col(embedding_model_dims, on_disk)\n.venv/lib/python3.12/site-packages/mem0/vector_stores/qdrant.py:83: in create_col\n    response = self.list_cols()\n.venv/lib/python3.12/site-packages/mem0/vector_stores/qdrant.py:200: in list_cols\n    return self.client.get_collections()\n.venv/lib/python3.12/site-packages/qdrant_client/qdrant_client.py:2214: in get_collections\n    return self._client.get_collections(**kwargs)\n.venv/lib/python3.12/site-packages/qdrant_client/qdrant_remote.py:2571: in get_collections\n    self.http.collections_api.get_collections().result\n.venv/lib/python3.12/site-packages/qdrant_client/http/api/collections_api.py:330: in get_collections\n    return self._build_for_get_collections()\n.venv/lib/python3.12/site-packages/qdrant_client/http/api/collections_api.py:159: in _build_for_get_collections\n    return self.api_client.request(\n.venv/lib/python3.12/site-packages/qdrant_client/http/api_client.py:90: in request\n    return self.send(request, type_)\n.venv/lib/python3.12/site-packages/qdrant_client/http/api_client.py:107: in send\n    response = self.middleware(request, self.send_inner)\n.venv/lib/python3.12/site-packages/qdrant_client/http/api_client.py:240: in __call__\n    return call_next(request)\n.venv/lib/python3.12/site-packages/qdrant_client/http/api_client.py:131: in send_inner\n    raise ResponseHandlingException(e)\nE   qdrant_client.http.exceptions.ResponseHandlingException: timed out\n\nDuring handling of the above exception, another exception occurred:\ntests/integration_mem0/test_peptide_coaching_scenario.py:101: in peptide_coach\n    pytest.fail(f\"Failed to initialize peptide coach: {str(e)}\")\nE   Failed: Failed to initialize peptide coach: timed out","steps":[],"attachments":[{"uid":"a2214a2a68ec7610","name":"Exception","source":"a2214a2a68ec7610.txt","type":"text/plain","size":45}],"parameters":[],"shouldDisplayMessage":true,"stepsCount":0,"attachmentsCount":1,"hasContent":true,"attachmentStep":false},"afterStages":[],"labels":[{"name":"severity","value":"normal"},{"name":"story","value":"Initial Greeting"},{"name":"feature","value":"Peptide Health Coaching"},{"name":"epic","value":"Mem0 Real-World Applications"},{"name":"tag","value":"api"},{"name":"parentSuite","value":"tests.integration_mem0"},{"name":"suite","value":"test_peptide_coaching_scenario"},{"name":"subSuite","value":"TestPeptideCoachingScenario"},{"name":"host","value":"samis-MacBook-Pro.local"},{"name":"thread","value":"29173-MainThread"},{"name":"framework","value":"pytest"},{"name":"language","value":"cpython3"},{"name":"package","value":"tests.integration_mem0.test_peptide_coaching_scenario"},{"name":"resultFormat","value":"allure2"}],"parameters":[],"links":[],"hidden":true,"retry":true,"extra":{"categories":[],"tags":["api"]},"source":"c553a4f5a1d3b863.json","parameterValues":[]}